Workbook

Sheet Pascal
A1: =IF(ISBLANK(Termine!B1),"",Termine!B1) -> Datum | B1: =IF(ISBLANK(Termine!C1),"",Termine!C1) -> Wochentag | C1: =IF(ISBLANK(Termine!D1),"",Termine!D1) -> Pascal Fäthke | D1: Projekt/Ordner | E1: =IF(ISBLANK(Termine!G1),"",Termine!G1) -> Adresse | F1: =IF(ISBLANK(Termine!H1),"",Termine!H1) -> Ansprechpartner | G1: =IF(ISBLANK(Termine!I1),"",Termine!I1) -> Auftrag | H1: =IF(ISBLANK(Termine!J1),"",Termine!J1) -> Bemerkungen
A2: =termine!#ref! -> #NAME? | B2: =IF(ISBLANK(termine!#ref!),"",termine!#ref!) -> #NAME? | C2: =IF(ISBLANK(termine!#ref!),"",termine!#ref!) -> #NAME? | D2: =IF(ISBLANK(termine!#ref!),"",termine!#ref!) -> #NAME? | E2: =IF(ISBLANK(termine!#ref!),"",termine!#ref!) -> #NAME? | F2: =IF(ISBLANK(termine!#ref!),"",termine!#ref!) -> #NAME? | G2: =IF(ISBLANK(termine!#ref!),"",termine!#ref!) -> #NAME? | H2: =IF(ISBLANK(termine!#ref!),"",termine!#ref!) -> #NAME?
A3: =termine!#ref! -> #NAME? | B3: =IF(ISBLANK(termine!#ref!),"",termine!#ref!) -> #NAME? | C3: =IF(ISBLANK(termine!#ref!),"",termine!#ref!) -> #NAME? | D3: =IF(ISBLANK(termine!#ref!),"",termine!#ref!) -> #NAME? | E3: =IF(ISBLANK(termine!#ref!),"",termine!#ref!) -> #NAME? | F3: =IF(ISBLANK(termine!#ref!),"",termine!#ref!) -> #NAME? | G3: =IF(ISBLANK(termine!#ref!),"",termine!#ref!) -> #NAME? | H3: =IF(ISBLANK(termine!#ref!),"",termine!#ref!) -> #NAME?
A4: =termine!#ref! -> #NAME? | B4: =IF(ISBLANK(termine!#ref!),"",termine!#ref!) -> #NAME? | C4: =IF(ISBLANK(termine!#ref!),"",termine!#ref!) -> #NAME? | D4: =IF(ISBLANK(termine!#ref!),"",termine!#ref!) -> #NAME? | E4: =IF(ISBLANK(termine!#ref!),"",termine!#ref!) -> #NAME? | F4: =IF(ISBLANK(termine!#ref!),"",termine!#ref!) -> #NAME? | G4: =IF(ISBLANK(termine!#ref!),"",termine!#ref!) -> #NAME? | H4: =IF(ISBLANK(termine!#ref!),"",termine!#ref!) -> #NAME?
A5: =termine!#ref! -> #NAME? | B5: =IF(ISBLANK(termine!#ref!),"",termine!#ref!) -> #NAME? | C5: =IF(ISBLANK(termine!#ref!),"",termine!#ref!) -> #NAME? | D5: =IF(ISBLANK(termine!#ref!),"",termine!#ref!) -> #NAME? | E5: =IF(ISBLANK(termine!#ref!),"",termine!#ref!) -> #NAME? | F5: =IF(ISBLANK(termine!#ref!),"",termine!#ref!) -> #NAME? | G5: =IF(ISBLANK(termine!#ref!),"",termine!#ref!) -> #NAME? | H5: =IF(ISBLANK(termine!#ref!),"",termine!#ref!) -> #NAME?
A6: =termine!#ref! -> #NAME? | B6: =IF(ISBLANK(termine!#ref!),"",termine!#ref!) -> #NAME? | C6: =IF(ISBLANK(termine!#ref!),"",termine!#ref!) -> #NAME? | D6: =IF(ISBLANK(termine!#ref!),"",termine!#ref!) -> #NAME? | E6: =IF(ISBLANK(termine!#ref!),"",termine!#ref!) -> #NAME? | F6: =IF(ISBLANK(termine!#ref!),"",termine!#ref!) -> #NAME? | G6: =IF(ISBLANK(termine!#ref!),"",termine!#ref!) -> #NAME? | H6: =IF(ISBLANK(termine!#ref!),"",termine!#ref!) -> #NAME?
A7: =termine!#ref! -> #NAME? | B7: =IF(ISBLANK(termine!#ref!),"",termine!#ref!) -> #NAME? | C7: =IF(ISBLANK(termine!#ref!),"",termine!#ref!) -> #NAME? | D7: =IF(ISBLANK(termine!#ref!),"",termine!#ref!) -> #NAME? | E7: =IF(ISBLANK(termine!#ref!),"",termine!#ref!) -> #NAME? | F7: =IF(ISBLANK(termine!#ref!),"",termine!#ref!) -> #NAME? | G7: =IF(ISBLANK(termine!#ref!),"",termine!#ref!) -> #NAME? | H7: =IF(ISBLANK(termine!#ref!),"",termine!#ref!) -> #NAME?
A8: =termine!#ref! -> #NAME? | B8: =IF(ISBLANK(termine!#ref!),"",termine!#ref!) -> #NAME? | C8: =IF(ISBLANK(termine!#ref!),"",termine!#ref!) -> #NAME? | D8: =IF(ISBLANK(termine!#ref!),"",termine!#ref!) -> #NAME? | E8: =IF(ISBLANK(termine!#ref!),"",termine!#ref!) -> #NAME? | F8: =IF(ISBLANK(termine!#ref!),"",termine!#ref!) -> #NAME? | G8: =IF(ISBLANK(termine!#ref!),"",termine!#ref!) -> #NAME? | H8: =IF(ISBLANK(termine!#ref!),"",termine!#ref!) -> #NAME?
A9: =termine!#ref! -> #NAME? | B9: =IF(ISBLANK(termine!#ref!),"",termine!#ref!) -> #NAME? | C9: =IF(ISBLANK(termine!#ref!),"",termine!#ref!) -> #NAME? | D9: =IF(ISBLANK(termine!#ref!),"",termine!#ref!) -> #NAME? | E9: =IF(ISBLANK(termine!#ref!),"",termine!#ref!) -> #NAME? | F9: =IF(ISBLANK(termine!#ref!),"",termine!#ref!) -> #NAME? | G9: =IF(ISBLANK(termine!#ref!),"",termine!#ref!) -> #NAME? | H9: =IF(ISBLANK(termine!#ref!),"",termine!#ref!) -> #NAME?
A10: =termine!#ref! -> #NAME? | B10: =IF(ISBLANK(termine!#ref!),"",termine!#ref!) -> #NAME? | C10: =IF(ISBLANK(termine!#ref!),"",termine!#ref!) -> #NAME? | D10: =IF(ISBLANK(termine!#ref!),"",termine!#ref!) -> #NAME? | E10: =IF(ISBLANK(termine!#ref!),"",termine!#ref!) -> #NAME? | F10: =IF(ISBLANK(termine!#ref!),"",termine!#ref!) -> #NAME? | G10: =IF(ISBLANK(termine!#ref!),"",termine!#ref!) -> #NAME? | H10: =IF(ISBLANK(termine!#ref!),"",termine!#ref!) -> #NAME?
A11: =termine!#ref! -> #NAME? | B11: =IF(ISBLANK(termine!#ref!),"",termine!#ref!) -> #NAME? | C11: =IF(ISBLANK(termine!#ref!),"",termine!#ref!) -> #NAME? | D11: =IF(ISBLANK(termine!#ref!),"",termine!#ref!) -> #NAME? | E11: =IF(ISBLANK(termine!#ref!),"",termine!#ref!) -> #NAME? | F11: =IF(ISBLANK(termine!#ref!),"",termine!#ref!) -> #NAME? | G11: =IF(ISBLANK(termine!#ref!),"",termine!#ref!) -> #NAME? | H11: =IF(ISBLANK(termine!#ref!),"",termine!#ref!) -> #NAME?
A12: =termine!#ref! -> #NAME? | B12: =IF(ISBLANK(termine!#ref!),"",termine!#ref!) -> #NAME? | C12: =IF(ISBLANK(termine!#ref!),"",termine!#ref!) -> #NAME? | D12: =IF(ISBLANK(termine!#ref!),"",termine!#ref!) -> #NAME? | E12: =IF(ISBLANK(termine!#ref!),"",termine!#ref!) -> #NAME? | F12: =IF(ISBLANK(termine!#ref!),"",termine!#ref!) -> #NAME? | G12: =IF(ISBLANK(termine!#ref!),"",termine!#ref!) -> #NAME? | H12: =IF(ISBLANK(termine!#ref!),"",termine!#ref!) -> #NAME?
A13: =termine!#ref! -> #NAME? | B13: =IF(ISBLANK(termine!#ref!),"",termine!#ref!) -> #NAME? | C13: =IF(ISBLANK(termine!#ref!),"",termine!#ref!) -> #NAME? | D13: =IF(ISBLANK(termine!#ref!),"",termine!#ref!) -> #NAME? | E13: =IF(ISBLANK(termine!#ref!),"",termine!#ref!) -> #NAME? | F13: =IF(ISBLANK(termine!#ref!),"",termine!#ref!) -> #NAME? | G13: =IF(ISBLANK(termine!#ref!),"",termine!#ref!) -> #NAME? | H13: =IF(ISBLANK(termine!#ref!),"",termine!#ref!) -> #NAME?
... A126: =termine!#ref! -> #NAME? | B126: =IF(ISBLANK(termine!#ref!),"",termine!#ref!) -> #NAME? | C126: =IF(ISBLANK(termine!#ref!),"",termine!#ref!) -> #NAME? | D126: =IF(ISBLANK(termine!#ref!),"",termine!#ref!) -> #NAME? | E126: =IF(ISBLANK(termine!#ref!),"",termine!#ref!) -> #NAME? | F126: =IF(ISBLANK(termine!#ref!),"",termine!#ref!) -> #NAME? | G126: =IF(ISBLANK(termine!#ref!),"",termine!#ref!) -> #NAME? | H126: =IF(ISBLANK(termine!#ref!),"",termine!#ref!) -> #NAME?
A127: =termine!#ref! -> #NAME? | B127: =IF(ISBLANK(termine!#ref!),"",termine!#ref!) -> #NAME? | C127: =IF(ISBLANK(termine!#ref!),"",termine!#ref!) -> #NAME? | D127: =wennd130(ISBLANK(termine!#ref!),"",termine!#ref!) -> #NAME? | E127: =IF(ISBLANK(termine!#ref!),"",termine!#ref!) -> #NAME? | F127: =IF(ISBLANK(termine!#ref!),"",termine!#ref!) -> #NAME? | G127: =IF(ISBLANK(termine!#ref!),"",termine!#ref!) -> #NAME? | H127: =IF(ISBLANK(termine!#ref!),"",termine!#ref!) -> #NAME?
A128: =termine!#ref! -> #NAME? | B128: =IF(ISBLANK(termine!#ref!),"",termine!#ref!) -> #NAME? | C128: =IF(ISBLANK(termine!#ref!),"",termine!#ref!) -> #NAME? | D128: =IF(ISBLANK(termine!#ref!),"",termine!#ref!) -> #NAME? | E128: =IF(ISBLANK(termine!#ref!),"",termine!#ref!) -> #NAME? | F128: =IF(ISBLANK(termine!#ref!),"",termine!#ref!) -> #NAME? | G128: =IF(ISBLANK(termine!#ref!),"",termine!#ref!) -> #NAME? | H128: =IF(ISBLANK(termine!#ref!),"",termine!#ref!) -> #NAME?
A129: =termine!#ref! -> #NAME? | B129: =IF(ISBLANK(termine!#ref!),"",termine!#ref!) -> #NAME? | C129: =IF(ISBLANK(termine!#ref!),"",termine!#ref!) -> #NAME? | D129: =IF(ISBLANK(termine!#ref!),"",termine!#ref!) -> #NAME? | E129: =IF(ISBLANK(termine!#ref!),"",termine!#ref!) -> #NAME? | F129: =IF(ISBLANK(termine!#ref!),"",termine!#ref!) -> #NAME? | G129: =IF(ISBLANK(termine!#ref!),"",termine!#ref!) -> #NAME? | H129: =IF(ISBLANK(termine!#ref!),"",termine!#ref!) -> #NAME?
A130: =termine!#ref! -> #NAME? | B130: =IF(ISBLANK(termine!#ref!),"",termine!#ref!) -> #NAME? | C130: =IF(ISBLANK(termine!#ref!),"",termine!#ref!) -> #NAME? | D130: =IF(ISBLANK(termine!#ref!),"",termine!#ref!) -> #NAME? | E130: =IF(ISBLANK(termine!#ref!),"",termine!#ref!) -> #NAME? | F130: =IF(ISBLANK(termine!#ref!),"",termine!#ref!) -> #NAME? | G130: =IF(ISBLANK(termine!#ref!),"",termine!#ref!) -> #NAME? | H130: =IF(ISBLANK(termine!#ref!),"",termine!#ref!) -> #NAME?
A131: =termine!#ref! -> #NAME? | B131: =IF(ISBLANK(termine!#ref!),"",termine!#ref!) -> #NAME? | C131: =IF(ISBLANK(termine!#ref!),"",termine!#ref!) -> #NAME? | D131: =IF(ISBLANK(termine!#ref!),"",termine!#ref!) -> #NAME? | E131: =IF(ISBLANK(termine!#ref!),"",termine!#ref!) -> #NAME? | F131: =IF(ISBLANK(termine!#ref!),"",termine!#ref!) -> #NAME? | G131: =IF(ISBLANK(termine!#ref!),"",termine!#ref!) -> #NAME? | H131: =IF(ISBLANK(termine!#ref!),"",termine!#ref!) -> #NAME?
A132: =termine!#ref! -> #NAME? | B132: =IF(ISBLANK(termine!#ref!),"",termine!#ref!) -> #NAME? | C132: =IF(ISBLANK(termine!#ref!),"",termine!#ref!) -> #NAME? | D132: =IF(ISBLANK(termine!#ref!),"",termine!#ref!) -> #NAME? | E132: =IF(ISBLANK(termine!#ref!),"",termine!#ref!) -> #NAME? | F132: =IF(ISBLANK(termine!#ref!),"",termine!#ref!) -> #NAME? | G132: =IF(ISBLANK(termine!#ref!),"",termine!#ref!) -> #NAME? | H132: =IF(ISBLANK(termine!#ref!),"",termine!#ref!) -> #NAME?
A133: =termine!#ref! -> #NAME? | B133: =IF(ISBLANK(termine!#ref!),"",termine!#ref!) -> #NAME? | C133: =IF(ISBLANK(termine!#ref!),"",termine!#ref!) -> #NAME? | D133: =IF(ISBLANK(termine!#ref!),"",termine!#ref!) -> #NAME? | E133: =IF(ISBLANK(termine!#ref!),"",termine!#ref!) -> #NAME? | F133: =IF(ISBLANK(termine!#ref!),"",termine!#ref!) -> #NAME? | G133: =IF(ISBLANK(termine!#ref!),"",termine!#ref!) -> #NAME? | H133: =IF(ISBLANK(termine!#ref!),"",termine!#ref!) -> #NAME?
A134: =termine!#ref! -> #NAME? | B134: =IF(ISBLANK(termine!#ref!),"",termine!#ref!) -> #NAME? | C134: =IF(ISBLANK(termine!#ref!),"",termine!#ref!) -> #NAME? | D134: =IF(ISBLANK(termine!#ref!),"",termine!#ref!) -> #NAME? | E134: =IF(ISBLANK(termine!#ref!),"",termine!#ref!) -> #NAME? | F134: =IF(ISBLANK(termine!#ref!),"",termine!#ref!) -> #NAME? | G134: =IF(ISBLANK(termine!#ref!),"",termine!#ref!) -> #NAME? | H134: =IF(ISBLANK(termine!#ref!),"",termine!#ref!) -> #NAME?
A135: =termine!#ref! -> #NAME? | B135: =IF(ISBLANK(termine!#ref!),"",termine!#ref!) -> #NAME? | C135: =IF(ISBLANK(termine!#ref!),"",termine!#ref!) -> #NAME? | D135: =IF(ISBLANK(termine!#ref!),"",termine!#ref!) -> #NAME? | E135: =IF(ISBLANK(termine!#ref!),"",termine!#ref!) -> #NAME? | F135: =IF(ISBLANK(termine!#ref!),"",termine!#ref!) -> #NAME? | G135: =IF(ISBLANK(termine!#ref!),"",termine!#ref!) -> #NAME? | H135: =IF(ISBLANK(termine!#ref!),"",termine!#ref!) -> #NAME?
A136: =termine!#ref! -> #NAME? | B136: =IF(ISBLANK(termine!#ref!),"",termine!#ref!) -> #NAME? | C136: =IF(ISBLANK(termine!#ref!),"",termine!#ref!) -> #NAME? | D136: =IF(ISBLANK(termine!#ref!),"",termine!#ref!) -> #NAME? | E136: =IF(ISBLANK(termine!#ref!),"",termine!#ref!) -> #NAME? | F136: =IF(ISBLANK(termine!#ref!),"",termine!#ref!) -> #NAME? | G136: =IF(ISBLANK(termine!#ref!),"",termine!#ref!) -> #NAME? | H136: =IF(ISBLANK(termine!#ref!),"",termine!#ref!) -> #NAME?
A137: =termine!#ref! -> #NAME? | B137: =IF(ISBLANK(termine!#ref!),"",termine!#ref!) -> #NAME? | C137: =IF(ISBLANK(termine!#ref!),"",termine!#ref!) -> #NAME? | D137: =IF(ISBLANK(termine!#ref!),"",termine!#ref!) -> #NAME? | E137: =IF(ISBLANK(termine!#ref!),"",termine!#ref!) -> #NAME? | F137: =IF(ISBLANK(termine!#ref!),"",termine!#ref!) -> #NAME? | G137: =IF(ISBLANK(termine!#ref!),"",termine!#ref!) -> #NAME? | H137: =IF(ISBLANK(termine!#ref!),"",termine!#ref!) -> #NAME?
A138: =termine!#ref! -> #NAME? | B138: =IF(ISBLANK(termine!#ref!),"",termine!#ref!) -> #NAME? | C138: =IF(ISBLANK(termine!#ref!),"",termine!#ref!) -> #NAME? | D138: =IF(ISBLANK(termine!#ref!),"",termine!#ref!) -> #NAME? | E138: =IF(ISBLANK(termine!#ref!),"",termine!#ref!) -> #NAME? | F138: =IF(ISBLANK(termine!#ref!),"",termine!#ref!) -> #NAME? | G138: =IF(ISBLANK(termine!#ref!),"",termine!#ref!) -> #NAME? | H138: =IF(ISBLANK(termine!#ref!),"",termine!#ref!) -> #NAME?
A139: =termine!#ref! -> #NAME? | B139: =IF(ISBLANK(termine!#ref!),"",termine!#ref!) -> #NAME? | C139: =IF(ISBLANK(termine!#ref!),"",termine!#ref!) -> #NAME? | D139: =IF(ISBLANK(termine!#ref!),"",termine!#ref!) -> #NAME? | E139: =IF(ISBLANK(termine!#ref!),"",termine!#ref!) -> #NAME? | F139: =IF(ISBLANK(termine!#ref!),"",termine!#ref!) -> #NAME? | G139: =IF(ISBLANK(termine!#ref!),"",termine!#ref!) -> #NAME? | H139: =IF(ISBLANK(termine!#ref!),"",termine!#ref!) -> #NAME?
... A190: =termine!#ref! -> #NAME? | B190: =IF(ISBLANK(termine!#ref!),"",termine!#ref!) -> #NAME? | C190: =IF(ISBLANK(termine!#ref!),"",termine!#ref!) -> #NAME? | D190: =IF(ISBLANK(termine!#ref!),"",termine!#ref!) -> #NAME? | E190: =IF(ISBLANK(termine!#ref!),"",termine!#ref!) -> #NAME? | F190: =IF(ISBLANK(termine!#ref!),"",termine!#ref!) -> #NAME? | G190: =IF(ISBLANK(termine!#ref!),"",termine!#ref!) -> #NAME? | H190: =IF(ISBLANK(termine!#ref!),"",termine!#ref!) -> #NAME?
A191: =Termine!B2 -> 46023 | B191: =IF(ISBLANK(Termine!C2),"",Termine!C2) -> Donnerstag | C191: =IF(ISBLANK(Termine!D2),"",Termine!D2) -> Feiertag | D191: =IF(ISBLANK(Termine!F2),"",Termine!F2) | E191: =IF(ISBLANK(Termine!G2),"",Termine!G2) | F191: =IF(ISBLANK(Termine!H2),"",Termine!H2) | G191: =IF(ISBLANK(Termine!I2),"",Termine!I2) | H191: =IF(ISBLANK(Termine!J2),"",Termine!J2)
A192: =Termine!B3 -> 46024 | B192: =IF(ISBLANK(Termine!C3),"",Termine!C3) -> Freitag | C192: =IF(ISBLANK(Termine!D3),"",Termine!D3) -> frei | D192: =IF(ISBLANK(Termine!F3),"",Termine!F3) | E192: =IF(ISBLANK(Termine!G3),"",Termine!G3) | F192: =IF(ISBLANK(Termine!H3),"",Termine!H3) | G192: =IF(ISBLANK(Termine!I3),"",Termine!I3) | H192: =IF(ISBLANK(Termine!J3),"",Termine!J3)
A194: =Termine!B5 -> 46026 | B194: =IF(ISBLANK(Termine!C5),"",Termine!C5) -> Sonntag | C194: =IF(ISBLANK(Termine!D5),"",Termine!D5) | D194: =IF(ISBLANK(Termine!F5),"",Termine!F5) | E194: =IF(ISBLANK(Termine!G5),"",Termine!G5) | F194: =IF(ISBLANK(Termine!H5),"",Termine!H5) | G194: =IF(ISBLANK(Termine!I5),"",Termine!I5) | H194: =IF(ISBLANK(Termine!J5),"",Termine!J5)
A195: =Termine!B6 -> 46027 | B195: =IF(ISBLANK(Termine!C6),"",Termine!C6) -> Montag | C195: =IF(ISBLANK(Termine!D6),"",Termine!D6) -> frei | D195: =IF(ISBLANK(Termine!F6),"",Termine!F6) | E195: =IF(ISBLANK(Termine!G6),"",Termine!G6) | F195: =IF(ISBLANK(Termine!H6),"",Termine!H6) | G195: =IF(ISBLANK(Termine!I6),"",Termine!I6) | H195: =IF(ISBLANK(Termine!J6),"",Termine!J6)
A196: =Termine!B7 -> 46028 | B196: =IF(ISBLANK(Termine!C7),"",Termine!C7) -> Dienstag | C196: =IF(ISBLANK(Termine!D7),"",Termine!D7) -> Feiertag | D196: =IF(ISBLANK(Termine!F7),"",Termine!F7) | E196: =IF(ISBLANK(Termine!G7),"",Termine!G7) | F196: =IF(ISBLANK(Termine!H7),"",Termine!H7) | G196: =IF(ISBLANK(Termine!I7),"",Termine!I7) | H196: =IF(ISBLANK(Termine!J7),"",Termine!J7)
A197: =Termine!B8 -> 46029 | B197: =IF(ISBLANK(Termine!C8),"",Termine!C8) -> Mittwoch | C197: =IF(ISBLANK(Termine!D8),"",Termine!D8) -> frei | D197: =IF(ISBLANK(Termine!F8),"",Termine!F8) | E197: =IF(ISBLANK(Termine!G8),"",Termine!G8) | F197: =IF(ISBLANK(Termine!H8),"",Termine!H8) | G197: =IF(ISBLANK(Termine!I8),"",Termine!I8) | H197: =IF(ISBLANK(Termine!J8),"",Termine!J8)
A198: =Termine!B9 -> 46030 | B198: =IF(ISBLANK(Termine!C9),"",Termine!C9) -> Donnerstag | C198: =IF(ISBLANK(Termine!D9),"",Termine!D9) -> frei | D198: =IF(ISBLANK(Termine!F9),"",Termine!F9) | E198: =IF(ISBLANK(Termine!G9),"",Termine!G9) | F198: =IF(ISBLANK(Termine!H9),"",Termine!H9) | G198: =IF(ISBLANK(Termine!I9),"",Termine!I9) | H198: =IF(ISBLANK(Termine!J9),"",Termine!J9)
A199: =Termine!B10 -> 46031 | B199: =IF(ISBLANK(Termine!C10),"",Termine!C10) -> Freitag | C199: =IF(ISBLANK(Termine!D10),"",Termine!D10) -> frei | D199: =IF(ISBLANK(Termine!F10),"",Termine!F10) | E199: =IF(ISBLANK(Termine!G10),"",Termine!G10) | F199: =IF(ISBLANK(Termine!H10),"",Termine!H10) | G199: =IF(ISBLANK(Termine!I10),"",Termine!I10) | H199: =IF(ISBLANK(Termine!J10),"",Termine!J10)
A200: =Termine!B11 -> 46032 | B200: =IF(ISBLANK(Termine!C11),"",Termine!C11) -> Samstag | C200: =IF(ISBLANK(Termine!D11),"",Termine!D11) | D200: =IF(ISBLANK(Termine!F11),"",Termine!F11) | E200: =IF(ISBLANK(Termine!G11),"",Termine!G11) | F200: =IF(ISBLANK(Termine!H11),"",Termine!H11) | G200: =IF(ISBLANK(Termine!I11),"",Termine!I11) | H200: =IF(ISBLANK(Termine!J11),"",Termine!J11)
A202: =Termine!B13 -> 46034 | B202: =IF(ISBLANK(Termine!C13),"",Termine!C13) -> Montag | C202: =IF(ISBLANK(Termine!D13),"",Termine!D13) -> frei | D202: =IF(ISBLANK(Termine!F13),"",Termine!F13) | E202: =IF(ISBLANK(Termine!G13),"",Termine!G13) | F202: =IF(ISBLANK(Termine!H13),"",Termine!H13) | G202: =IF(ISBLANK(Termine!I13),"",Termine!I13) | H202: =IF(ISBLANK(Termine!J13),"",Termine!J13)
A203: =Termine!B14 -> 46035 | B203: =IF(ISBLANK(Termine!C14),"",Termine!C14) -> Dienstag | C203: =IF(ISBLANK(Termine!D14),"",Termine!D14) -> frei | D203: =IF(ISBLANK(Termine!F14),"",Termine!F14) | E203: =IF(ISBLANK(Termine!G14),"",Termine!G14) | F203: =IF(ISBLANK(Termine!H14),"",Termine!H14) | G203: =IF(ISBLANK(Termine!I14),"",Termine!I14) | H203: =IF(ISBLANK(Termine!J14),"",Termine!J14)
A204: =Termine!B15 -> 46036 | B204: =IF(ISBLANK(Termine!C15),"",Termine!C15) -> Mittwoch | C204: =IF(ISBLANK(Termine!D15),"",Termine!D15) -> frei | D204: =IF(ISBLANK(Termine!F15),"",Termine!F15) | E204: =IF(ISBLANK(Termine!G15),"",Termine!G15) | F204: =IF(ISBLANK(Termine!H15),"",Termine!H15) | G204: =IF(ISBLANK(Termine!I15),"",Termine!I15) | H204: =IF(ISBLANK(Termine!J15),"",Termine!J15)
...

Sheet Niklas
A1: =IF(ISBLANK(Termine!Q1),"",Termine!Q1) -> Datum | B1: =IF(ISBLANK(Termine!R1),"",Termine!R1) -> Wochentag | C1: =IF(ISBLANK(Termine!S1),"",Termine!S1) -> Niklas Helmchen | D1: Projekt/Ordner | E1: =IF(ISBLANK(Termine!V1),"",Termine!V1) -> Adresse | F1: =IF(ISBLANK(Termine!W1),"",Termine!W1) -> Ansprechpartner | G1: =IF(ISBLANK(Termine!X1),"",Termine!X1) -> Auftrag | H1: =IF(ISBLANK(Termine!Y1),"",Termine!Y1) -> Bemerkungen
A2: =termine!#ref! -> #NAME? | B2: =IF(ISBLANK(termine!#ref!),"",termine!#ref!) -> #NAME? | C2: =IF(ISBLANK(termine!#ref!),"",termine!#ref!) -> #NAME? | D2: =IF(ISBLANK(termine!#ref!),"",termine!#ref!) -> #NAME? | E2: =IF(ISBLANK(termine!#ref!),"",termine!#ref!) -> #NAME? | F2: =IF(ISBLANK(termine!#ref!),"",termine!#ref!) -> #NAME? | G2: =IF(ISBLANK(termine!#ref!),"",termine!#ref!) -> #NAME? | H2: =IF(ISBLANK(termine!#ref!),"",termine!#ref!) -> #NAME?
A3: =termine!#ref! -> #NAME? | B3: =IF(ISBLANK(termine!#ref!),"",termine!#ref!) -> #NAME? | C3: =IF(ISBLANK(termine!#ref!),"",termine!#ref!) -> #NAME? | D3: =IF(ISBLANK(termine!#ref!),"",termine!#ref!) -> #NAME? | E3: =IF(ISBLANK(termine!#ref!),"",termine!#ref!) -> #NAME? | F3: =IF(ISBLANK(termine!#ref!),"",termine!#ref!) -> #NAME? | G3: =IF(ISBLANK(termine!#ref!),"",termine!#ref!) -> #NAME? | H3: =IF(ISBLANK(termine!#ref!),"",termine!#ref!) -> #NAME?
A4: =termine!#ref! -> #NAME? | B4: =IF(ISBLANK(termine!#ref!),"",termine!#ref!) -> #NAME? | C4: =IF(ISBLANK(termine!#ref!),"",termine!#ref!) -> #NAME? | D4: =IF(ISBLANK(termine!#ref!),"",termine!#ref!) -> #NAME? | E4: =IF(ISBLANK(termine!#ref!),"",termine!#ref!) -> #NAME? | F4: =IF(ISBLANK(termine!#ref!),"",termine!#ref!) -> #NAME? | G4: =IF(ISBLANK(termine!#ref!),"",termine!#ref!) -> #NAME? | H4: =IF(ISBLANK(termine!#ref!),"",termine!#ref!) -> #NAME?
A5: =termine!#ref! -> #NAME? | B5: =IF(ISBLANK(termine!#ref!),"",termine!#ref!) -> #NAME? | C5: =IF(ISBLANK(termine!#ref!),"",termine!#ref!) -> #NAME? | D5: =IF(ISBLANK(termine!#ref!),"",termine!#ref!) -> #NAME? | E5: =IF(ISBLANK(termine!#ref!),"",termine!#ref!) -> #NAME? | F5: =IF(ISBLANK(termine!#ref!),"",termine!#ref!) -> #NAME? | G5: =IF(ISBLANK(termine!#ref!),"",termine!#ref!) -> #NAME? | H5: =IF(ISBLANK(termine!#ref!),"",termine!#ref!) -> #NAME?
A6: =termine!#ref! -> #NAME? | B6: =IF(ISBLANK(termine!#ref!),"",termine!#ref!) -> #NAME? | C6: =IF(ISBLANK(termine!#ref!),"",termine!#ref!) -> #NAME? | D6: =IF(ISBLANK(termine!#ref!),"",termine!#ref!) -> #NAME? | E6: =IF(ISBLANK(termine!#ref!),"",termine!#ref!) -> #NAME? | F6: =IF(ISBLANK(termine!#ref!),"",termine!#ref!) -> #NAME? | G6: =IF(ISBLANK(termine!#ref!),"",termine!#ref!) -> #NAME? | H6: =IF(ISBLANK(termine!#ref!),"",termine!#ref!) -> #NAME?
A7: =termine!#ref! -> #NAME? | B7: =IF(ISBLANK(termine!#ref!),"",termine!#ref!) -> #NAME? | C7: =IF(ISBLANK(termine!#ref!),"",termine!#ref!) -> #NAME? | D7: =IF(ISBLANK(termine!#ref!),"",termine!#ref!) -> #NAME? | E7: =IF(ISBLANK(termine!#ref!),"",termine!#ref!) -> #NAME? | F7: =IF(ISBLANK(termine!#ref!),"",termine!#ref!) -> #NAME? | G7: =IF(ISBLANK(termine!#ref!),"",termine!#ref!) -> #NAME? | H7: =IF(ISBLANK(termine!#ref!),"",termine!#ref!) -> #NAME?
A8: =termine!#ref! -> #NAME? | B8: =IF(ISBLANK(termine!#ref!),"",termine!#ref!) -> #NAME? | C8: =IF(ISBLANK(termine!#ref!),"",termine!#ref!) -> #NAME? | D8: =IF(ISBLANK(termine!#ref!),"",termine!#ref!) -> #NAME? | E8: =IF(ISBLANK(termine!#ref!),"",termine!#ref!) -> #NAME? | F8: =IF(ISBLANK(termine!#ref!),"",termine!#ref!) -> #NAME? | G8: =IF(ISBLANK(termine!#ref!),"",termine!#ref!) -> #NAME? | H8: =IF(ISBLANK(termine!#ref!),"",termine!#ref!) -> #NAME?
A9: =termine!#ref! -> #NAME? | B9: =IF(ISBLANK(termine!#ref!),"",termine!#ref!) -> #NAME? | C9: =IF(ISBLANK(termine!#ref!),"",termine!#ref!) -> #NAME? | D9: =IF(ISBLANK(termine!#ref!),"",termine!#ref!) -> #NAME? | E9: =IF(ISBLANK(termine!#ref!),"",termine!#ref!) -> #NAME? | F9: =IF(ISBLANK(termine!#ref!),"",termine!#ref!) -> #NAME? | G9: =IF(ISBLANK(termine!#ref!),"",termine!#ref!) -> #NAME? | H9: =IF(ISBLANK(termine!#ref!),"",termine!#ref!) -> #NAME?
A10: =termine!#ref! -> #NAME? | B10: =IF(ISBLANK(termine!#ref!),"",termine!#ref!) -> #NAME? | C10: =IF(ISBLANK(termine!#ref!),"",termine!#ref!) -> #NAME? | D10: =IF(ISBLANK(termine!#ref!),"",termine!#ref!) -> #NAME? | E10: =IF(ISBLANK(termine!#ref!),"",termine!#ref!) -> #NAME? | F10: =IF(ISBLANK(termine!#ref!),"",termine!#ref!) -> #NAME? | G10: =IF(ISBLANK(termine!#ref!),"",termine!#ref!) -> #NAME? | H10: =IF(ISBLANK(termine!#ref!),"",termine!#ref!) -> #NAME?
A11: =termine!#ref! -> #NAME? | B11: =IF(ISBLANK(termine!#ref!),"",termine!#ref!) -> #NAME? | C11: =IF(ISBLANK(termine!#ref!),"",termine!#ref!) -> #NAME? | D11: =IF(ISBLANK(termine!#ref!),"",termine!#ref!) -> #NAME? | E11: =IF(ISBLANK(termine!#ref!),"",termine!#ref!) -> #NAME? | F11: =IF(ISBLANK(termine!#ref!),"",termine!#ref!) -> #NAME? | G11: =IF(ISBLANK(termine!#ref!),"",termine!#ref!) -> #NAME? | H11: =IF(ISBLANK(termine!#ref!),"",termine!#ref!) -> #NAME?
A12: =termine!#ref! -> #NAME? | B12: =IF(ISBLANK(termine!#ref!),"",termine!#ref!) -> #NAME? | C12: =IF(ISBLANK(termine!#ref!),"",termine!#ref!) -> #NAME? | D12: =IF(ISBLANK(termine!#ref!),"",termine!#ref!) -> #NAME? | E12: =IF(ISBLANK(termine!#ref!),"",termine!#ref!) -> #NAME? | F12: =IF(ISBLANK(termine!#ref!),"",termine!#ref!) -> #NAME? | G12: =IF(ISBLANK(termine!#ref!),"",termine!#ref!) -> #NAME? | H12: =IF(ISBLANK(termine!#ref!),"",termine!#ref!) -> #NAME?
A13: =termine!#ref! -> #NAME? | B13: =IF(ISBLANK(termine!#ref!),"",termine!#ref!) -> #NAME? | C13: =IF(ISBLANK(termine!#ref!),"",termine!#ref!) -> #NAME? | D13: =IF(ISBLANK(termine!#ref!),"",termine!#ref!) -> #NAME? | E13: =IF(ISBLANK(termine!#ref!),"",termine!#ref!) -> #NAME? | F13: =IF(ISBLANK(termine!#ref!),"",termine!#ref!) -> #NAME? | G13: =IF(ISBLANK(termine!#ref!),"",termine!#ref!) -> #NAME? | H13: =IF(ISBLANK(termine!#ref!),"",termine!#ref!) -> #NAME?
... A89: =termine!#ref! -> #NAME? | B89: =IF(ISBLANK(termine!#ref!),"",termine!#ref!) -> #NAME? | C89: =IF(ISBLANK(termine!#ref!),"",termine!#ref!) -> #NAME? | D89: =IF(ISBLANK(termine!#ref!),"",termine!#ref!) -> #NAME? | E89: =IF(ISBLANK(termine!#ref!),"",termine!#ref!) -> #NAME? | F89: =IF(ISBLANK(termine!#ref!),"",termine!#ref!) -> #NAME? | G89: =IF(ISBLANK(termine!#ref!),"",termine!#ref!) -> #NAME? | H89: =IF(ISBLANK(termine!#ref!),"",termine!#ref!) -> #NAME?
A90: =termine!#ref! -> #NAME? | B90: =IF(ISBLANK(termine!#ref!),"",termine!#ref!) -> #NAME? | C90: =IF(ISBLANK(termine #REF!),"",termine #REF!) -> #VALUE! | D90: =IF(ISBLANK(termine!#ref!),"",termine!#ref!) -> #NAME? | E90: =IF(ISBLANK(termine!#ref!),"",termine!#ref!) -> #NAME? | F90: =IF(ISBLANK(termine!#ref!),"",termine!#ref!) -> #NAME? | G90: =IF(ISBLANK(termine!#ref!),"",termine!#ref!) -> #NAME? | H90: =IF(ISBLANK(termine!#ref!),"",termine!#ref!) -> #NAME?
A91: =termine!#ref! -> #NAME? | B91: =IF(ISBLANK(termine!#ref!),"",termine!#ref!) -> #NAME? | C91: =IF(ISBLANK(termine!#ref!),"",termine!#ref!) -> #NAME? | D91: =IF(ISBLANK(termine!#ref!),"",termine!#ref!) -> #NAME? | E91: =IF(ISBLANK(termine!#ref!),"",termine!#ref!) -> #NAME? | F91: =IF(ISBLANK(termine!#ref!),"",termine!#ref!) -> #NAME? | G91: =IF(ISBLANK(termine!#ref!),"",termine!#ref!) -> #NAME? | H91: =IF(ISBLANK(termine!#ref!),"",termine!#ref!) -> #NAME?
A92: =termine!#ref! -> #NAME? | B92: =IF(ISBLANK(termine!#ref!),"",termine!#ref!) -> #NAME? | C92: =IF(ISBLANK(termine!#ref!),"",termine!#ref!) -> #NAME? | D92: =IF(ISBLANK(termine!#ref!),"",termine!#ref!) -> #NAME? | E92: =IF(ISBLANK(termine!#ref!),"",termine!#ref!) -> #NAME? | F92: =IF(ISBLANK(termine!#ref!),"",termine!#ref!) -> #NAME? | G92: =IF(ISBLANK(termine!#ref!),"",termine!#ref!) -> #NAME? | H92: =IF(ISBLANK(termine!#ref!),"",termine!#ref!) -> #NAME?
A93: =termine!#ref! -> #NAME? | B93: =IF(ISBLANK(termine!#ref!),"",termine!#ref!) -> #NAME? | C93: =IF(ISBLANK(termine!#ref!),"",termine!#ref!) -> #NAME? | D93: =IF(ISBLANK(termine!#ref!),"",termine!#ref!) -> #NAME? | E93: =IF(ISBLANK(termine!#ref!),"",termine!#ref!) -> #NAME? | F93: =IF(ISBLANK(termine!#ref!),"",termine!#ref!) -> #NAME? | G93: =IF(ISBLANK(termine!#ref!),"",termine!#ref!) -> #NAME? | H93: =IF(ISBLANK(termine!#ref!),"",termine!#ref!) -> #NAME?
A94: =termine!#ref! -> #NAME? | B94: =IF(ISBLANK(termine!#ref!),"",termine!#ref!) -> #NAME? | C94: =IF(ISBLANK(termine!#ref!),"",termine!#ref!) -> #NAME? | D94: =IF(ISBLANK(termine!#ref!),"",termine!#ref!) -> #NAME? | E94: =IF(ISBLANK(termine!#ref!),"",termine!#ref!) -> #NAME? | F94: =IF(ISBLANK(termine!#ref!),"",termine!#ref!) -> #NAME? | G94: =IF(ISBLANK(termine!#ref!),"",termine!#ref!) -> #NAME? | H94: =IF(ISBLANK(termine!#ref!),"",termine!#ref!) -> #NAME?
A95: =termine!#ref! -> #NAME? | B95: =IF(ISBLANK(termine!#ref!),"",termine!#ref!) -> #NAME? | C95: =IF(ISBLANK(termine!#ref!),"",termine!#ref!) -> #NAME? | D95: =IF(ISBLANK(termine!#ref!),"",termine!#ref!) -> #NAME? | E95: =IF(ISBLANK(termine!#ref!),"",termine!#ref!) -> #NAME? | F95: =IF(ISBLANK(termine!#ref!),"",termine!#ref!) -> #NAME? | G95: =IF(ISBLANK(termine!#ref!),"",termine!#ref!) -> #NAME? | H95: =IF(ISBLANK(termine!#ref!),"",termine!#ref!) -> #NAME?
A96: =termine!#ref! -> #NAME? | B96: =IF(ISBLANK(termine!#ref!),"",termine!#ref!) -> #NAME? | C96: =IF(ISBLANK(termine!#ref!),"",termine!#ref!) -> #NAME? | D96: =IF(ISBLANK(termine!#ref!),"",termine!#ref!) -> #NAME? | E96: =IF(ISBLANK(termine!#ref!),"",termine!#ref!) -> #NAME? | F96: =IF(ISBLANK(termine!#ref!),"",termine!#ref!) -> #NAME? | G96: =IF(ISBLANK(termine!#ref!),"",termine!#ref!) -> #NAME? | H96: =IF(ISBLANK(termine!#ref!),"",termine!#ref!) -> #NAME?
A97: =termine!#ref! -> #NAME? | B97: =IF(ISBLANK(termine!#ref!),"",termine!#ref!) -> #NAME? | C97: =IF(ISBLANK(termine!#ref!),"",termine!#ref!) -> #NAME? | D97: =IF(ISBLANK(termine!#ref!),"",termine!#ref!) -> #NAME? | E97: =IF(ISBLANK(termine!#ref!),"",termine!#ref!) -> #NAME? | F97: =IF(ISBLANK(termine!#ref!),"",termine!#ref!) -> #NAME? | G97: =IF(ISBLANK(termine!#ref!),"",termine!#ref!) -> #NAME? | H97: =IF(ISBLANK(termine!#ref!),"",termine!#ref!) -> #NAME?
A98: =termine!#ref! -> #NAME? | B98: =IF(ISBLANK(termine!#ref!),"",termine!#ref!) -> #NAME? | C98: =IF(ISBLANK(termine!#ref!),"",termine!#ref!) -> #NAME? | D98: =IF(ISBLANK(termine!#ref!),"",termine!#ref!) -> #NAME? | E98: =IF(ISBLANK(termine!#ref!),"",termine!#ref!) -> #NAME? | F98: =IF(ISBLANK(termine!#ref!),"",termine!#ref!) -> #NAME? | G98: =IF(ISBLANK(termine!#ref!),"",termine!#ref!) -> #NAME? | H98: =IF(ISBLANK(termine!#ref!),"",termine!#ref!) -> #NAME?
A99: =termine!#ref! -> #NAME? | B99: =IF(ISBLANK(termine!#ref!),"",termine!#ref!) -> #NAME? | C99: =IF(ISBLANK(termine!#ref!),"",termine!#ref!) -> #NAME? | D99: =IF(ISBLANK(termine!#ref!),"",termine!#ref!) -> #NAME? | E99: =IF(ISBLANK(termine!#ref!),"",termine!#ref!) -> #NAME? | F99: =IF(ISBLANK(termine!#ref!),"",termine!#ref!) -> #NAME? | G99: =IF(ISBLANK(termine!#ref!),"",termine!#ref!) -> #NAME? | H99: =IF(ISBLANK(termine!#ref!),"",termine!#ref!) -> #NAME?
A100: =termine!#ref! -> #NAME? | B100: =IF(ISBLANK(termine!#ref!),"",termine!#ref!) -> #NAME? | C100: =IF(ISBLANK(termine!#ref!),"",termine!#ref!) -> #NAME? | D100: =IF(ISBLANK(termine!#ref!),"",termine!#ref!) -> #NAME? | E100: =IF(ISBLANK(termine!#ref!),"",termine!#ref!) -> #NAME? | F100: =IF(ISBLANK(termine!#ref!),"",termine!#ref!) -> #NAME? | G100: =IF(ISBLANK(termine!#ref!),"",termine!#ref!) -> #NAME? | H100: =IF(ISBLANK(termine!#ref!),"",termine!#ref!) -> #NAME?
A101: =termine!#ref! -> #NAME? | B101: =IF(ISBLANK(termine!#ref!),"",termine!#ref!) -> #NAME? | C101: =IF(ISBLANK(termine!#ref!),"",termine!#ref!) -> #NAME? | D101: =IF(ISBLANK(termine!#ref!),"",termine!#ref!) -> #NAME? | E101: =IF(ISBLANK(termine!#ref!),"",termine!#ref!) -> #NAME? | F101: =IF(ISBLANK(termine!#ref!),"",termine!#ref!) -> #NAME? | G101: =IF(ISBLANK(termine!#ref!),"",termine!#ref!) -> #NAME? | H101: =IF(ISBLANK(termine!#ref!),"",termine!#ref!) -> #NAME?
A102: =termine!#ref! -> #NAME? | B102: =IF(ISBLANK(termine!#ref!),"",termine!#ref!) -> #NAME? | C102: =IF(ISBLANK(termine!#ref!),"",termine!#ref!) -> #NAME? | D102: =IF(ISBLANK(termine!#ref!),"",termine!#ref!) -> #NAME? | E102: =IF(ISBLANK(termine!#ref!),"",termine!#ref!) -> #NAME? | F102: =IF(ISBLANK(termine!#ref!),"",termine!#ref!) -> #NAME? | G102: =IF(ISBLANK(termine!#ref!),"",termine!#ref!) -> #NAME? | H102: =IF(ISBLANK(termine!#ref!),"",termine!#ref!) -> #NAME?
... A190: =termine!#ref! -> #NAME? | B190: =IF(ISBLANK(termine!#ref!),"",termine!#ref!) -> #NAME? | C190: =IF(ISBLANK(termine!#ref!),"",termine!#ref!) -> #NAME? | D190: =IF(ISBLANK(termine!#ref!),"",termine!#ref!) -> #NAME? | E190: =IF(ISBLANK(termine!#ref!),"",termine!#ref!) -> #NAME? | F190: =IF(ISBLANK(termine!#ref!),"",termine!#ref!) -> #NAME? | G190: =IF(ISBLANK(termine!#ref!),"",termine!#ref!) -> #NAME? | H190: =IF(ISBLANK(termine!#ref!),"",termine!#ref!) -> #NAME?
A191: =Termine!Q2 -> 46023 | B191: =IF(ISBLANK(Termine!R2),"",Termine!R2) -> Donnerstag | C191: =IF(ISBLANK(Termine!S2),"",Termine!S2) -> Feiertag | D191: =IF(ISBLANK(Termine!U2),"",Termine!U2) | E191: =IF(ISBLANK(Termine!V2),"",Termine!V2) | F191: =IF(ISBLANK(Termine!W2),"",Termine!W2) | G191: =IF(ISBLANK(Termine!X2),"",Termine!X2) | H191: =IF(ISBLANK(Termine!Y2),"",Termine!Y2)
A192: =Termine!Q3 -> 46024 | B192: =IF(ISBLANK(Termine!R3),"",Termine!R3) -> Freitag | C192: =IF(ISBLANK(Termine!S3),"",Termine!S3) -> frei | D192: =IF(ISBLANK(Termine!U3),"",Termine!U3) | E192: =IF(ISBLANK(Termine!V3),"",Termine!V3) | F192: =IF(ISBLANK(Termine!W3),"",Termine!W3) | G192: =IF(ISBLANK(Termine!X3),"",Termine!X3) | H192: =IF(ISBLANK(Termine!Y3),"",Termine!Y3)
A193: =Termine!Q4 -> 46025 | B193: =IF(ISBLANK(Termine!R4),"",Termine!R4) -> Samstag | C193: =IF(ISBLANK(Termine!S4),"",Termine!S4) | D193: =IF(ISBLANK(Termine!U4),"",Termine!U4) | E193: =IF(ISBLANK(Termine!V4),"",Termine!V4) | F193: =IF(ISBLANK(Termine!W4),"",Termine!W4) | G193: =IF(ISBLANK(Termine!X4),"",Termine!X4) | H193: =IF(ISBLANK(Termine!Y4),"",Termine!Y4)
A194: =Termine!Q5 -> 46026 | B194: =IF(ISBLANK(Termine!R5),"",Termine!R5) -> Sonntag | C194: =IF(ISBLANK(Termine!S5),"",Termine!S5) | D194: =IF(ISBLANK(Termine!U5),"",Termine!U5) | E194: =IF(ISBLANK(Termine!V5),"",Termine!V5) | F194: =IF(ISBLANK(Termine!W5),"",Termine!W5) | G194: =IF(ISBLANK(Termine!X5),"",Termine!X5) | H194: =IF(ISBLANK(Termine!Y5),"",Termine!Y5)
A195: =Termine!Q6 -> 46027 | B195: =IF(ISBLANK(Termine!R6),"",Termine!R6) -> Montag | C195: =IF(ISBLANK(Termine!S6),"",Termine!S6) -> frei | D195: =IF(ISBLANK(Termine!U6),"",Termine!U6) | E195: =IF(ISBLANK(Termine!V6),"",Termine!V6) | F195: =IF(ISBLANK(Termine!W6),"",Termine!W6) | G195: =IF(ISBLANK(Termine!X6),"",Termine!X6) | H195: =IF(ISBLANK(Termine!Y6),"",Termine!Y6)
A196: =Termine!Q7 -> 46028 | B196: =IF(ISBLANK(Termine!R7),"",Termine!R7) -> Dienstag | C196: =IF(ISBLANK(Termine!S7),"",Termine!S7) -> Feiertag | D196: =IF(ISBLANK(Termine!U7),"",Termine!U7) | E196: =IF(ISBLANK(Termine!V7),"",Termine!V7) | F196: =IF(ISBLANK(Termine!W7),"",Termine!W7) | G196: =IF(ISBLANK(Termine!X7),"",Termine!X7) | H196: =IF(ISBLANK(Termine!Y7),"",Termine!Y7)
A197: =Termine!Q8 -> 46029 | B197: =IF(ISBLANK(Termine!R8),"",Termine!R8) -> Mittwoch | C197: =IF(ISBLANK(Termine!S8),"",Termine!S8) -> Krank | D197: =IF(ISBLANK(Termine!U8),"",Termine!U8) | E197: =IF(ISBLANK(Termine!V8),"",Termine!V8) | F197: =IF(ISBLANK(Termine!W8),"",Termine!W8) | G197: =IF(ISBLANK(Termine!X8),"",Termine!X8) | H197: =IF(ISBLANK(Termine!Y8),"",Termine!Y8)
A198: =Termine!Q9 -> 46030 | B198: =IF(ISBLANK(Termine!R9),"",Termine!R9) -> Donnerstag | C198: =IF(ISBLANK(Termine!S9),"",Termine!S9) -> Krank | D198: =IF(ISBLANK(Termine!U9),"",Termine!U9) | E198: =IF(ISBLANK(Termine!V9),"",Termine!V9) | F198: =IF(ISBLANK(Termine!W9),"",Termine!W9) | G198: =IF(ISBLANK(Termine!X9),"",Termine!X9) | H198: =IF(ISBLANK(Termine!Y9),"",Termine!Y9)
A199: =Termine!Q10 -> 46031 | B199: =IF(ISBLANK(Termine!R10),"",Termine!R10) -> Freitag | C199: =IF(ISBLANK(Termine!S10),"",Termine!S10) -> Krank | D199: =IF(ISBLANK(Termine!U10),"",Termine!U10) | E199: =IF(ISBLANK(Termine!V10),"",Termine!V10) | F199: =IF(ISBLANK(Termine!W10),"",Termine!W10) | G199: =IF(ISBLANK(Termine!X10),"",Termine!X10) | H199: =IF(ISBLANK(Termine!Y10),"",Termine!Y10)
A200: =Termine!Q11 -> 46032 | B200: =IF(ISBLANK(Termine!R11),"",Termine!R11) -> Samstag | C200: =IF(ISBLANK(Termine!S11),"",Termine!S11) | D200: =IF(ISBLANK(Termine!U11),"",Termine!U11) | E200: =IF(ISBLANK(Termine!V11),"",Termine!V11) | F200: =IF(ISBLANK(Termine!W11),"",Termine!W11) | G200: =IF(ISBLANK(Termine!X11),"",Termine!X11) | H200: =IF(ISBLANK(Termine!Y11),"",Termine!Y11)
A201: =Termine!Q12 -> 46033 | B201: =IF(ISBLANK(Termine!R12),"",Termine!R12) -> Sonntag | C201: =IF(ISBLANK(Termine!S12),"",Termine!S12) | D201: =IF(ISBLANK(Termine!U12),"",Termine!U12) | E201: =IF(ISBLANK(Termine!V12),"",Termine!V12) | F201: =IF(ISBLANK(Termine!W12),"",Termine!W12) | G201: =IF(ISBLANK(Termine!X12),"",Termine!X12) | H201: =IF(ISBLANK(Termine!Y12),"",Termine!Y12)
A202: =Termine!Q13 -> 46034 | B202: =IF(ISBLANK(Termine!R13),"",Termine!R13) -> Montag | C202: =IF(ISBLANK(Termine!S13),"",Termine!S13) -> Arbeit | D202: =IF(ISBLANK(Termine!U13),"",Termine!U13) -> Buxtehude | E202: =IF(ISBLANK(Termine!V13),"",Termine!V13) | F202: =IF(ISBLANK(Termine!W13),"",Termine!W13) -> Anton | G202: =IF(ISBLANK(Termine!X13),"",Termine!X13) | H202: =IF(ISBLANK(Termine!Y13),"",Termine!Y13)
...

Sheet Hagen
A1: =IF(ISBLANK(Termine!AF1),"",Termine!AF1) -> Datum | B1: =IF(ISBLANK(Termine!AG1),"",Termine!AG1) -> Wochentag | C1: =IF(ISBLANK(Termine!AH1),"",Termine!AH1) -> Hagen Schmidt | D1: =IF(ISBLANK(Termine!AJ1),"",Termine!AJ1) -> Projekt3 | E1: =IF(ISBLANK(Termine!AK1),"",Termine!AK1) -> Adresse | F1: =IF(ISBLANK(Termine!AL1),"",Termine!AL1) -> Ansprechpartner | G1: =IF(ISBLANK(Termine!AM1),"",Termine!AM1) -> Auftrag | H1: =IF(ISBLANK(Termine!AN1),"",Termine!AN1) -> Bemerkungen
A2: =termine!#ref! -> #NAME? | B2: =IF(ISBLANK(termine!#ref!),"",termine!#ref!) -> #NAME? | C2: =IF(ISBLANK(termine!#ref!),"",termine!#ref!) -> #NAME? | D2: =IF(ISBLANK(termine!#ref!),"",termine!#ref!) -> #NAME? | E2: =IF(ISBLANK(termine!#ref!),"",termine!#ref!) -> #NAME? | F2: =IF(ISBLANK(termine!#ref!),"",termine!#ref!) -> #NAME? | G2: =IF(ISBLANK(termine!#ref!),"",termine!#ref!) -> #NAME? | H2: =IF(ISBLANK(termine!#ref!),"",termine!#ref!) -> #NAME?
A3: =termine!#ref! -> #NAME? | B3: =IF(ISBLANK(termine!#ref!),"",termine!#ref!) -> #NAME? | C3: =IF(ISBLANK(termine!#ref!),"",termine!#ref!) -> #NAME? | D3: =IF(ISBLANK(termine!#ref!),"",termine!#ref!) -> #NAME? | E3: =IF(ISBLANK(termine!#ref!),"",termine!#ref!) -> #NAME? | F3: =IF(ISBLANK(termine!#ref!),"",termine!#ref!) -> #NAME? | G3: =IF(ISBLANK(termine!#ref!),"",termine!#ref!) -> #NAME? | H3: =IF(ISBLANK(termine!#ref!),"",termine!#ref!) -> #NAME?
A4: =termine!#ref! -> #NAME? | B4: =IF(ISBLANK(termine!#ref!),"",termine!#ref!) -> #NAME? | C4: =IF(ISBLANK(termine!#ref!),"",termine!#ref!) -> #NAME? | D4: =IF(ISBLANK(termine!#ref!),"",termine!#ref!) -> #NAME? | E4: =IF(ISBLANK(termine!#ref!),"",termine!#ref!) -> #NAME? | F4: =IF(ISBLANK(termine!#ref!),"",termine!#ref!) -> #NAME? | G4: =IF(ISBLANK(termine!#ref!),"",termine!#ref!) -> #NAME? | H4: =IF(ISBLANK(termine!#ref!),"",termine!#ref!) -> #NAME?
A5: =termine!#ref! -> #NAME? | B5: =IF(ISBLANK(termine!#ref!),"",termine!#ref!) -> #NAME? | C5: =IF(ISBLANK(termine!#ref!),"",termine!#ref!) -> #NAME? | D5: =IF(ISBLANK(termine!#ref!),"",termine!#ref!) -> #NAME? | E5: =IF(ISBLANK(termine!#ref!),"",termine!#ref!) -> #NAME? | F5: =IF(ISBLANK(termine!#ref!),"",termine!#ref!) -> #NAME? | G5: =IF(ISBLANK(termine!#ref!),"",termine!#ref!) -> #NAME? | H5: =IF(ISBLANK(termine!#ref!),"",termine!#ref!) -> #NAME?
A6: =termine!#ref! -> #NAME? | B6: =IF(ISBLANK(termine!#ref!),"",termine!#ref!) -> #NAME? | C6: =IF(ISBLANK(termine!#ref!),"",termine!#ref!) -> #NAME? | D6: =IF(ISBLANK(termine!#ref!),"",termine!#ref!) -> #NAME? | E6: =IF(ISBLANK(termine!#ref!),"",termine!#ref!) -> #NAME? | F6: =IF(ISBLANK(termine!#ref!),"",termine!#ref!) -> #NAME? | G6: =IF(ISBLANK(termine!#ref!),"",termine!#ref!) -> #NAME? | H6: =IF(ISBLANK(termine!#ref!),"",termine!#ref!) -> #NAME?
A7: =termine!#ref! -> #NAME? | B7: =IF(ISBLANK(termine!#ref!),"",termine!#ref!) -> #NAME? | C7: =IF(ISBLANK(termine!#ref!),"",termine!#ref!) -> #NAME? | D7: =IF(ISBLANK(termine!#ref!),"",termine!#ref!) -> #NAME? | E7: =IF(ISBLANK(termine!#ref!),"",termine!#ref!) -> #NAME? | F7: =IF(ISBLANK(termine!#ref!),"",termine!#ref!) -> #NAME? | G7: =IF(ISBLANK(termine!#ref!),"",termine!#ref!) -> #NAME? | H7: =IF(ISBLANK(termine!#ref!),"",termine!#ref!) -> #NAME?
A8: =termine!#ref! -> #NAME? | B8: =IF(ISBLANK(termine!#ref!),"",termine!#ref!) -> #NAME? | C8: =IF(ISBLANK(termine!#ref!),"",termine!#ref!) -> #NAME? | D8: =IF(ISBLANK(termine!#ref!),"",termine!#ref!) -> #NAME? | E8: =IF(ISBLANK(termine!#ref!),"",termine!#ref!) -> #NAME? | F8: =IF(ISBLANK(termine!#ref!),"",termine!#ref!) -> #NAME? | G8: =IF(ISBLANK(termine!#ref!),"",termine!#ref!) -> #NAME? | H8: =IF(ISBLANK(termine!#ref!),"",termine!#ref!) -> #NAME?
A9: =termine!#ref! -> #NAME? | B9: =IF(ISBLANK(termine!#ref!),"",termine!#ref!) -> #NAME? | C9: =IF(ISBLANK(termine!#ref!),"",termine!#ref!) -> #NAME? | D9: =IF(ISBLANK(termine!#ref!),"",termine!#ref!) -> #NAME? | E9: =IF(ISBLANK(termine!#ref!),"",termine!#ref!) -> #NAME? | F9: =IF(ISBLANK(termine!#ref!),"",termine!#ref!) -> #NAME? | G9: =IF(ISBLANK(termine!#ref!),"",termine!#ref!) -> #NAME? | H9: =IF(ISBLANK(termine!#ref!),"",termine!#ref!) -> #NAME?
A10: =termine!#ref! -> #NAME? | B10: =IF(ISBLANK(termine!#ref!),"",termine!#ref!) -> #NAME? | C10: =IF(ISBLANK(termine!#ref!),"",termine!#ref!) -> #NAME? | D10: =IF(ISBLANK(termine!#ref!),"",termine!#ref!) -> #NAME? | E10: =IF(ISBLANK(termine!#ref!),"",termine!#ref!) -> #NAME? | F10: =IF(ISBLANK(termine!#ref!),"",termine!#ref!) -> #NAME? | G10: =IF(ISBLANK(termine!#ref!),"",termine!#ref!) -> #NAME? | H10: =IF(ISBLANK(termine!#ref!),"",termine!#ref!) -> #NAME?
A11: =termine!#ref! -> #NAME? | B11: =IF(ISBLANK(termine!#ref!),"",termine!#ref!) -> #NAME? | C11: =IF(ISBLANK(termine!#ref!),"",termine!#ref!) -> #NAME? | D11: =IF(ISBLANK(termine!#ref!),"",termine!#ref!) -> #NAME? | E11: =IF(ISBLANK(termine!#ref!),"",termine!#ref!) -> #NAME? | F11: =IF(ISBLANK(termine!#ref!),"",termine!#ref!) -> #NAME? | G11: =IF(ISBLANK(termine!#ref!),"",termine!#ref!) -> #NAME? | H11: =IF(ISBLANK(termine!#ref!),"",termine!#ref!) -> #NAME?
A12: =termine!#ref! -> #NAME? | B12: =IF(ISBLANK(termine!#ref!),"",termine!#ref!) -> #NAME? | C12: =IF(ISBLANK(termine!#ref!),"",termine!#ref!) -> #NAME? | D12: =IF(ISBLANK(termine!#ref!),"",termine!#ref!) -> #NAME? | E12: =IF(ISBLANK(termine!#ref!),"",termine!#ref!) -> #NAME? | F12: =IF(ISBLANK(termine!#ref!),"",termine!#ref!) -> #NAME? | G12: =IF(ISBLANK(termine!#ref!),"",termine!#ref!) -> #NAME? | H12: =IF(ISBLANK(termine!#ref!),"",termine!#ref!) -> #NAME?
A13: =termine!#ref! -> #NAME? | B13: =IF(ISBLANK(termine!#ref!),"",termine!#ref!) -> #NAME? | C13: =IF(ISBLANK(termine!#ref!),"",termine!#ref!) -> #NAME? | D13: =IF(ISBLANK(termine!#ref!),"",termine!#ref!) -> #NAME? | E13: =IF(ISBLANK(termine!#ref!),"",termine!#ref!) -> #NAME? | F13: =IF(ISBLANK(termine!#ref!),"",termine!#ref!) -> #NAME? | G13: =IF(ISBLANK(termine!#ref!),"",termine!#ref!) -> #NAME? | H13: =IF(ISBLANK(termine!#ref!),"",termine!#ref!) -> #NAME?
... A83: =termine!#ref! -> #NAME? | B83: =IF(ISBLANK(termine!#ref!),"",termine!#ref!) -> #NAME? | C83: =IF(ISBLANK(termine!#ref!),"",termine!#ref!) -> #NAME? | D83: =IF(ISBLANK(termine!#ref!),"",termine!#ref!) -> #NAME? | E83: =IF(ISBLANK(termine!#ref!),"",termine!#ref!) -> #NAME? | F83: =IF(ISBLANK(termine!#ref!),"",termine!#ref!) -> #NAME? | G83: =IF(ISBLANK(termine!#ref!),"",termine!#ref!) -> #NAME? | H83: =IF(ISBLANK(termine!#ref!),"",termine!#ref!) -> #NAME?
A84: =termine!#ref! -> #NAME? | B84: =IF(ISBLANK(termine!#ref!),"",termine!#ref!) -> #NAME? | C84: Urlaub | D84: =IF(ISBLANK(termine!#ref!),"",termine!#ref!) -> #NAME? | E84: =IF(ISBLANK(termine!#ref!),"",termine!#ref!) -> #NAME? | F84: =IF(ISBLANK(termine!#ref!),"",termine!#ref!) -> #NAME? | G84: =IF(ISBLANK(termine!#ref!),"",termine!#ref!) -> #NAME? | H84: =IF(ISBLANK(termine!#ref!),"",termine!#ref!) -> #NAME?
A85: =termine!#ref! -> #NAME? | B85: =IF(ISBLANK(termine!#ref!),"",termine!#ref!) -> #NAME? | C85: Urlaub | D85: =IF(ISBLANK(termine!#ref!),"",termine!#ref!) -> #NAME? | E85: =IF(ISBLANK(termine!#ref!),"",termine!#ref!) -> #NAME? | F85: =IF(ISBLANK(termine!#ref!),"",termine!#ref!) -> #NAME? | G85: =IF(ISBLANK(termine!#ref!),"",termine!#ref!) -> #NAME? | H85: =IF(ISBLANK(termine!#ref!),"",termine!#ref!) -> #NAME?
A86: =termine!#ref! -> #NAME? | B86: =IF(ISBLANK(termine!#ref!),"",termine!#ref!) -> #NAME? | C86: Urlaub | D86: =IF(ISBLANK(termine!#ref!),"",termine!#ref!) -> #NAME? | E86: =IF(ISBLANK(termine!#ref!),"",termine!#ref!) -> #NAME? | F86: =IF(ISBLANK(termine!#ref!),"",termine!#ref!) -> #NAME? | G86: =IF(ISBLANK(termine!#ref!),"",termine!#ref!) -> #NAME? | H86: =IF(ISBLANK(termine!#ref!),"",termine!#ref!) -> #NAME?
A87: =termine!#ref! -> #NAME? | B87: =IF(ISBLANK(termine!#ref!),"",termine!#ref!) -> #NAME? | C87: Urlaub | D87: =IF(ISBLANK(termine!#ref!),"",termine!#ref!) -> #NAME? | E87: =IF(ISBLANK(termine!#ref!),"",termine!#ref!) -> #NAME? | F87: =IF(ISBLANK(termine!#ref!),"",termine!#ref!) -> #NAME? | G87: =IF(ISBLANK(termine!#ref!),"",termine!#ref!) -> #NAME? | H87: =IF(ISBLANK(termine!#ref!),"",termine!#ref!) -> #NAME?
A88: =termine!#ref! -> #NAME? | B88: =IF(ISBLANK(termine!#ref!),"",termine!#ref!) -> #NAME? | C88: =IF(ISBLANK(termine!#ref!),"",termine!#ref!) -> #NAME? | D88: =IF(ISBLANK(termine!#ref!),"",termine!#ref!) -> #NAME? | E88: =IF(ISBLANK(termine!#ref!),"",termine!#ref!) -> #NAME? | F88: =IF(ISBLANK(termine!#ref!),"",termine!#ref!) -> #NAME? | G88: =IF(ISBLANK(termine!#ref!),"",termine!#ref!) -> #NAME? | H88: =IF(ISBLANK(termine!#ref!),"",termine!#ref!) -> #NAME?
A89: =termine!#ref! -> #NAME? | B89: =IF(ISBLANK(termine!#ref!),"",termine!#ref!) -> #NAME? | C89: =IF(ISBLANK(termine!#ref!),"",termine!#ref!) -> #NAME? | D89: =IF(ISBLANK(termine!#ref!),"",termine!#ref!) -> #NAME? | E89: =IF(ISBLANK(termine!#ref!),"",termine!#ref!) -> #NAME? | F89: =IF(ISBLANK(termine!#ref!),"",termine!#ref!) -> #NAME? | G89: =IF(ISBLANK(termine!#ref!),"",termine!#ref!) -> #NAME? | H89: =IF(ISBLANK(termine!#ref!),"",termine!#ref!) -> #NAME?
A90: =termine!#ref! -> #NAME? | B90: =IF(ISBLANK(termine!#ref!),"",termine!#ref!) -> #NAME? | C90: =IF(ISBLANK(termine!#ref!),"",termine!#ref!) -> #NAME? | D90: =IF(ISBLANK(termine!#ref!),"",termine!#ref!) -> #NAME? | E90: =IF(ISBLANK(termine!#ref!),"",termine!#ref!) -> #NAME? | F90: =IF(ISBLANK(termine!#ref!),"",termine!#ref!) -> #NAME? | G90: =IF(ISBLANK(termine!#ref!),"",termine!#ref!) -> #NAME? | H90: =IF(ISBLANK(termine!#ref!),"",termine!#ref!) -> #NAME?
A91: =termine!#ref! -> #NAME? | B91: =IF(ISBLANK(termine!#ref!),"",termine!#ref!) -> #NAME? | C91: =IF(ISBLANK(termine!#ref!),"",termine!#ref!) -> #NAME? | D91: =IF(ISBLANK(termine!#ref!),"",termine!#ref!) -> #NAME? | E91: =IF(ISBLANK(termine!#ref!),"",termine!#ref!) -> #NAME? | F91: =IF(ISBLANK(termine!#ref!),"",termine!#ref!) -> #NAME? | G91: =IF(ISBLANK(termine!#ref!),"",termine!#ref!) -> #NAME? | H91: =IF(ISBLANK(termine!#ref!),"",termine!#ref!) -> #NAME?
A92: =termine!#ref! -> #NAME? | B92: =IF(ISBLANK(termine!#ref!),"",termine!#ref!) -> #NAME? | C92: =IF(ISBLANK(termine!#ref!),"",termine!#ref!) -> #NAME? | D92: =IF(ISBLANK(termine!#ref!),"",termine!#ref!) -> #NAME? | E92: =IF(ISBLANK(termine!#ref!),"",termine!#ref!) -> #NAME? | F92: =IF(ISBLANK(termine!#ref!),"",termine!#ref!) -> #NAME? | G92: =IF(ISBLANK(termine!#ref!),"",termine!#ref!) -> #NAME? | H92: =IF(ISBLANK(termine!#ref!),"",termine!#ref!) -> #NAME?
A93: =termine!#ref! -> #NAME? | B93: =IF(ISBLANK(termine!#ref!),"",termine!#ref!) -> #NAME? | C93: =IF(ISBLANK(termine!#ref!),"",termine!#ref!) -> #NAME? | D93: =IF(ISBLANK(termine!#ref!),"",termine!#ref!) -> #NAME? | E93: =IF(ISBLANK(termine!#ref!),"",termine!#ref!) -> #NAME? | F93: =IF(ISBLANK(termine!#ref!),"",termine!#ref!) -> #NAME? | G93: =IF(ISBLANK(termine!#ref!),"",termine!#ref!) -> #NAME? | H93: =IF(ISBLANK(termine!#ref!),"",termine!#ref!) -> #NAME?
A94: =termine!#ref! -> #NAME? | B94: =IF(ISBLANK(termine!#ref!),"",termine!#ref!) -> #NAME? | C94: =IF(ISBLANK(termine!#ref!),"",termine!#ref!) -> #NAME? | D94: =IF(ISBLANK(termine!#ref!),"",termine!#ref!) -> #NAME? | E94: =IF(ISBLANK(termine!#ref!),"",termine!#ref!) -> #NAME? | F94: =IF(ISBLANK(termine!#ref!),"",termine!#ref!) -> #NAME? | G94: =IF(ISBLANK(termine!#ref!),"",termine!#ref!) -> #NAME? | H94: =IF(ISBLANK(termine!#ref!),"",termine!#ref!) -> #NAME?
A95: =termine!#ref! -> #NAME? | B95: =IF(ISBLANK(termine!#ref!),"",termine!#ref!) -> #NAME? | C95: =IF(ISBLANK(termine!#ref!),"",termine!#ref!) -> #NAME? | D95: =IF(ISBLANK(termine!#ref!),"",termine!#ref!) -> #NAME? | E95: =IF(ISBLANK(termine!#ref!),"",termine!#ref!) -> #NAME? | F95: =IF(ISBLANK(termine!#ref!),"",termine!#ref!) -> #NAME? | G95: =IF(ISBLANK(termine!#ref!),"",termine!#ref!) -> #NAME? | H95: =IF(ISBLANK(termine!#ref!),"",termine!#ref!) -> #NAME?
A96: =termine!#ref! -> #NAME? | B96: =IF(ISBLANK(termine!#ref!),"",termine!#ref!) -> #NAME? | C96: =IF(ISBLANK(termine!#ref!),"",termine!#ref!) -> #NAME? | D96: =IF(ISBLANK(termine!#ref!),"",termine!#ref!) -> #NAME? | E96: =IF(ISBLANK(termine!#ref!),"",termine!#ref!) -> #NAME? | F96: =IF(ISBLANK(termine!#ref!),"",termine!#ref!) -> #NAME? | G96: =IF(ISBLANK(termine!#ref!),"",termine!#ref!) -> #NAME? | H96: =IF(ISBLANK(termine!#ref!),"",termine!#ref!) -> #NAME?
A97: =termine!#ref! -> #NAME? | B97: =IF(ISBLANK(termine!#ref!),"",termine!#ref!) -> #NAME? | C97: =IF(ISBLANK(termine!#ref!),"",termine!#ref!) -> #NAME? | D97: =IF(ISBLANK(termine!#ref!),"",termine!#ref!) -> #NAME? | E97: =IF(ISBLANK(termine!#ref!),"",termine!#ref!) -> #NAME? | F97: =IF(ISBLANK(termine!#ref!),"",termine!#ref!) -> #NAME? | G97: =IF(ISBLANK(termine!#ref!),"",termine!#ref!) -> #NAME? | H97: =IF(ISBLANK(termine!#ref!),"",termine!#ref!) -> #NAME?
A98: =termine!#ref! -> #NAME? | B98: =IF(ISBLANK(termine!#ref!),"",termine!#ref!) -> #NAME? | C98: =IF(ISBLANK(termine!#ref!),"",termine!#ref!) -> #NAME? | D98: =IF(ISBLANK(termine!#ref!),"",termine!#ref!) -> #NAME? | E98: =IF(ISBLANK(termine!#ref!),"",termine!#ref!) -> #NAME? | F98: =IF(ISBLANK(termine!#ref!),"",termine!#ref!) -> #NAME? | G98: =IF(ISBLANK(termine!#ref!),"",termine!#ref!) -> #NAME? | H98: =IF(ISBLANK(termine!#ref!),"",termine!#ref!) -> #NAME?
A99: =termine!#ref! -> #NAME? | B99: =IF(ISBLANK(termine!#ref!),"",termine!#ref!) -> #NAME? | C99: =IF(ISBLANK(termine!#ref!),"",termine!#ref!) -> #NAME? | D99: =IF(ISBLANK(termine!#ref!),"",termine!#ref!) -> #NAME? | E99: =IF(ISBLANK(termine!#ref!),"",termine!#ref!) -> #NAME? | F99: =IF(ISBLANK(termine!#ref!),"",termine!#ref!) -> #NAME? | G99: =IF(ISBLANK(termine!#ref!),"",termine!#ref!) -> #NAME? | H99: =IF(ISBLANK(termine!#ref!),"",termine!#ref!) -> #NAME?
... A154: =termine!#ref! -> #NAME? | B154: =IF(ISBLANK(termine!#ref!),"",termine!#ref!) -> #NAME? | C154: =IF(ISBLANK(termine!#ref!),"",termine!#ref!) -> #NAME? | D154: =IF(ISBLANK(termine!#ref!),"",termine!#ref!) -> #NAME? | E154: =IF(ISBLANK(termine!#ref!),"",termine!#ref!) -> #NAME? | F154: =IF(ISBLANK(termine!#ref!),"",termine!#ref!) -> #NAME? | G154: =IF(ISBLANK(termine!#ref!),"",termine!#ref!) -> #NAME? | H154: =IF(ISBLANK(termine!#ref!),"",termine!#ref!) -> #NAME?
A155: =termine!#ref! -> #NAME? | B155: =IF(ISBLANK(termine!#ref!),"",termine!#ref!) -> #NAME? | C155: =IF(ISBLANK(termine!#ref!),"",termine!#ref!) -> #NAME? | D155: =IF(ISBLANK(termine!#ref!),"",termine!#ref!) -> #NAME? | F155: =IF(ISBLANK(termine!#ref!),"",termine!#ref!) -> #NAME? | G155: =IF(ISBLANK(termine!#ref!),"",termine!#ref!) -> #NAME? | H155: =IF(ISBLANK(termine!#ref!),"",termine!#ref!) -> #NAME?
A156: =termine!#ref! -> #NAME? | B156: =IF(ISBLANK(termine!#ref!),"",termine!#ref!) -> #NAME? | C156: =IF(ISBLANK(termine!#ref!),"",termine!#ref!) -> #NAME? | D156: =IF(ISBLANK(termine!#ref!),"",termine!#ref!) -> #NAME? | E156: =IF(ISBLANK(termine!#ref!),"",termine!#ref!) -> #NAME? | F156: =IF(ISBLANK(termine!#ref!),"",termine!#ref!) -> #NAME? | G156: =IF(ISBLANK(termine!#ref!),"",termine!#ref!) -> #NAME? | H156: =IF(ISBLANK(termine!#ref!),"",termine!#ref!) -> #NAME?
A157: =termine!#ref! -> #NAME? | B157: =IF(ISBLANK(termine!#ref!),"",termine!#ref!) -> #NAME? | C157: =IF(ISBLANK(termine!#ref!),"",termine!#ref!) -> #NAME? | D157: =IF(ISBLANK(termine!#ref!),"",termine!#ref!) -> #NAME? | E157: =IF(ISBLANK(termine!#ref!),"",termine!#ref!) -> #NAME? | F157: =IF(ISBLANK(termine!#ref!),"",termine!#ref!) -> #NAME? | G157: =IF(ISBLANK(termine!#ref!),"",termine!#ref!) -> #NAME? | H157: =IF(ISBLANK(termine!#ref!),"",termine!#ref!) -> #NAME?
A158: =termine!#ref! -> #NAME? | B158: =IF(ISBLANK(termine!#ref!),"",termine!#ref!) -> #NAME? | C158: =IF(ISBLANK(termine!#ref!),"",termine!#ref!) -> #NAME? | D158: =IF(ISBLANK(termine!#ref!),"",termine!#ref!) -> #NAME? | E158: =IF(ISBLANK(termine!#ref!),"",termine!#ref!) -> #NAME? | F158: =IF(ISBLANK(termine!#ref!),"",termine!#ref!) -> #NAME? | G158: =IF(ISBLANK(termine!#ref!),"",termine!#ref!) -> #NAME? | H158: =IF(ISBLANK(termine!#ref!),"",termine!#ref!) -> #NAME?
A159: =termine!#ref! -> #NAME? | B159: =IF(ISBLANK(termine!#ref!),"",termine!#ref!) -> #NAME? | C159: =IF(ISBLANK(termine!#ref!),"",termine!#ref!) -> #NAME? | D159: =IF(ISBLANK(termine!#ref!),"",termine!#ref!) -> #NAME? | E159: =IF(ISBLANK(termine!#ref!),"",termine!#ref!) -> #NAME? | F159: =IF(ISBLANK(termine!#ref!),"",termine!#ref!) -> #NAME? | G159: =IF(ISBLANK(termine!#ref!),"",termine!#ref!) -> #NAME? | H159: =IF(ISBLANK(termine!#ref!),"",termine!#ref!) -> #NAME?
A160: =termine!#ref! -> #NAME? | B160: =IF(ISBLANK(termine!#ref!),"",termine!#ref!) -> #NAME? | C160: =IF(ISBLANK(termine!#ref!),"",termine!#ref!) -> #NAME? | D160: =IF(ISBLANK(termine!#ref!),"",termine!#ref!) -> #NAME? | E160: =IF(ISBLANK(termine!#ref!),"",termine!#ref!) -> #NAME? | F160: =IF(ISBLANK(termine!#ref!),"",termine!#ref!) -> #NAME? | G160: =IF(ISBLANK(termine!#ref!),"",termine!#ref!) -> #NAME? | H160: =IF(ISBLANK(termine!#ref!),"",termine!#ref!) -> #NAME?
A161: =termine!#ref! -> #NAME? | B161: =IF(ISBLANK(termine!#ref!),"",termine!#ref!) -> #NAME? | C161: =IF(ISBLANK(termine!#ref!),"",termine!#ref!) -> #NAME? | D161: =IF(ISBLANK(termine!#ref!),"",termine!#ref!) -> #NAME? | E161: =IF(ISBLANK(termine!#ref!),"",termine!#ref!) -> #NAME? | F161: =IF(ISBLANK(termine!#ref!),"",termine!#ref!) -> #NAME? | G161: =IF(ISBLANK(termine!#ref!),"",termine!#ref!) -> #NAME? | H161: =IF(ISBLANK(termine!#ref!),"",termine!#ref!) -> #NAME?
A162: =termine!#ref! -> #NAME? | B162: =IF(ISBLANK(termine!#ref!),"",termine!#ref!) -> #NAME? | C162: =IF(ISBLANK(termine!#ref!),"",termine!#ref!) -> #NAME? | D162: =IF(ISBLANK(termine!#ref!),"",termine!#ref!) -> #NAME? | E162: =IF(ISBLANK(termine!#ref!),"",termine!#ref!) -> #NAME? | F162: =IF(ISBLANK(termine!#ref!),"",termine!#ref!) -> #NAME? | G162: =IF(ISBLANK(termine!#ref!),"",termine!#ref!) -> #NAME? | H162: =IF(ISBLANK(termine!#ref!),"",termine!#ref!) -> #NAME?
A163: =termine!#ref! -> #NAME? | B163: =IF(ISBLANK(termine!#ref!),"",termine!#ref!) -> #NAME? | C163: =IF(ISBLANK(termine!#ref!),"",termine!#ref!) -> #NAME? | D163: =IF(ISBLANK(termine!#ref!),"",termine!#ref!) -> #NAME? | E163: =IF(ISBLANK(termine!#ref!),"",termine!#ref!) -> #NAME? | F163: =IF(ISBLANK(termine!#ref!),"",termine!#ref!) -> #NAME? | G163: =IF(ISBLANK(termine!#ref!),"",termine!#ref!) -> #NAME? | H163: =IF(ISBLANK(termine!#ref!),"",termine!#ref!) -> #NAME?
...

Sheet Kevin
A1: =IF(ISBLANK(Termine!CN1),"",Termine!CN1) -> Datum | B1: =IF(ISBLANK(Termine!CO1),"",Termine!CO1) -> Wochentag | C1: =IF(ISBLANK(Termine!CP1),"",Termine!CP1) -> Kevin Koehn | D1: =IF(ISBLANK(Termine!CR1),"",Termine!CR1) -> Projekt4 | E1: =IF(ISBLANK(Termine!CS1),"",Termine!CS1) -> Adresse | F1: =IF(ISBLANK(Termine!CT1),"",Termine!CT1) -> Ansprechpartner | G1: =IF(ISBLANK(Termine!CU1),"",Termine!CU1) -> Auftrag | H1: =IF(ISBLANK(Termine!CV1),"",Termine!CV1) -> Bemerkungen
A2: =termine!#ref! -> #NAME? | B2: =IF(ISBLANK(termine!#ref!),"",termine!#ref!) -> #NAME? | C2: =IF(ISBLANK(termine!#ref!),"",termine!#ref!) -> #NAME? | D2: =IF(ISBLANK(termine!#ref!),"",termine!#ref!) -> #NAME? | E2: =IF(ISBLANK(termine!#ref!),"",termine!#ref!) -> #NAME? | F2: =IF(ISBLANK(termine!#ref!),"",termine!#ref!) -> #NAME? | G2: =IF(ISBLANK(termine!#ref!),"",termine!#ref!) -> #NAME? | H2: =IF(ISBLANK(termine!#ref!),"",termine!#ref!) -> #NAME?
A3: =termine!#ref! -> #NAME? | B3: =IF(ISBLANK(termine!#ref!),"",termine!#ref!) -> #NAME? | C3: =IF(ISBLANK(termine!#ref!),"",termine!#ref!) -> #NAME? | D3: =IF(ISBLANK(termine!#ref!),"",termine!#ref!) -> #NAME? | E3: =IF(ISBLANK(termine!#ref!),"",termine!#ref!) -> #NAME? | F3: =IF(ISBLANK(termine!#ref!),"",termine!#ref!) -> #NAME? | G3: =IF(ISBLANK(termine!#ref!),"",termine!#ref!) -> #NAME? | H3: =IF(ISBLANK(termine!#ref!),"",termine!#ref!) -> #NAME?
A4: =termine!#ref! -> #NAME? | B4: =IF(ISBLANK(termine!#ref!),"",termine!#ref!) -> #NAME? | C4: =IF(ISBLANK(termine!#ref!),"",termine!#ref!) -> #NAME? | D4: =IF(ISBLANK(termine!#ref!),"",termine!#ref!) -> #NAME? | E4: =IF(ISBLANK(termine!#ref!),"",termine!#ref!) -> #NAME? | F4: =IF(ISBLANK(termine!#ref!),"",termine!#ref!) -> #NAME? | G4: =IF(ISBLANK(termine!#ref!),"",termine!#ref!) -> #NAME? | H4: =IF(ISBLANK(termine!#ref!),"",termine!#ref!) -> #NAME?
A5: =termine!#ref! -> #NAME? | B5: =IF(ISBLANK(termine!#ref!),"",termine!#ref!) -> #NAME? | C5: =IF(ISBLANK(termine!#ref!),"",termine!#ref!) -> #NAME? | D5: =IF(ISBLANK(termine!#ref!),"",termine!#ref!) -> #NAME? | E5: =IF(ISBLANK(termine!#ref!),"",termine!#ref!) -> #NAME? | F5: =IF(ISBLANK(termine!#ref!),"",termine!#ref!) -> #NAME? | G5: =IF(ISBLANK(termine!#ref!),"",termine!#ref!) -> #NAME? | H5: =IF(ISBLANK(termine!#ref!),"",termine!#ref!) -> #NAME?
A6: =termine!#ref! -> #NAME? | B6: =IF(ISBLANK(termine!#ref!),"",termine!#ref!) -> #NAME? | C6: =IF(ISBLANK(termine!#ref!),"",termine!#ref!) -> #NAME? | D6: =IF(ISBLANK(termine!#ref!),"",termine!#ref!) -> #NAME? | E6: =IF(ISBLANK(termine!#ref!),"",termine!#ref!) -> #NAME? | F6: =IF(ISBLANK(termine!#ref!),"",termine!#ref!) -> #NAME? | G6: =IF(ISBLANK(termine!#ref!),"",termine!#ref!) -> #NAME? | H6: =IF(ISBLANK(termine!#ref!),"",termine!#ref!) -> #NAME?
A7: =termine!#ref! -> #NAME? | B7: =IF(ISBLANK(termine!#ref!),"",termine!#ref!) -> #NAME? | C7: =IF(ISBLANK(termine!#ref!),"",termine!#ref!) -> #NAME? | D7: =IF(ISBLANK(termine!#ref!),"",termine!#ref!) -> #NAME? | E7: =IF(ISBLANK(termine!#ref!),"",termine!#ref!) -> #NAME? | F7: =IF(ISBLANK(termine!#ref!),"",termine!#ref!) -> #NAME? | G7: =IF(ISBLANK(termine!#ref!),"",termine!#ref!) -> #NAME? | H7: =IF(ISBLANK(termine!#ref!),"",termine!#ref!) -> #NAME?
A8: =termine!#ref! -> #NAME? | B8: =IF(ISBLANK(termine!#ref!),"",termine!#ref!) -> #NAME? | C8: =IF(ISBLANK(termine!#ref!),"",termine!#ref!) -> #NAME? | D8: =IF(ISBLANK(termine!#ref!),"",termine!#ref!) -> #NAME? | E8: =IF(ISBLANK(termine!#ref!),"",termine!#ref!) -> #NAME? | F8: =IF(ISBLANK(termine!#ref!),"",termine!#ref!) -> #NAME? | G8: =IF(ISBLANK(termine!#ref!),"",termine!#ref!) -> #NAME? | H8: =IF(ISBLANK(termine!#ref!),"",termine!#ref!) -> #NAME?
A9: =termine!#ref! -> #NAME? | B9: =IF(ISBLANK(termine!#ref!),"",termine!#ref!) -> #NAME? | C9: =IF(ISBLANK(termine!#ref!),"",termine!#ref!) -> #NAME? | D9: =IF(ISBLANK(termine!#ref!),"",termine!#ref!) -> #NAME? | E9: =IF(ISBLANK(termine!#ref!),"",termine!#ref!) -> #NAME? | F9: =IF(ISBLANK(termine!#ref!),"",termine!#ref!) -> #NAME? | G9: =IF(ISBLANK(termine!#ref!),"",termine!#ref!) -> #NAME? | H9: =IF(ISBLANK(termine!#ref!),"",termine!#ref!) -> #NAME?
A10: =termine!#ref! -> #NAME? | B10: =IF(ISBLANK(termine!#ref!),"",termine!#ref!) -> #NAME? | C10: =IF(ISBLANK(termine!#ref!),"",termine!#ref!) -> #NAME? | D10: =IF(ISBLANK(termine!#ref!),"",termine!#ref!) -> #NAME? | E10: =IF(ISBLANK(termine!#ref!),"",termine!#ref!) -> #NAME? | F10: =IF(ISBLANK(termine!#ref!),"",termine!#ref!) -> #NAME? | G10: =IF(ISBLANK(termine!#ref!),"",termine!#ref!) -> #NAME? | H10: =IF(ISBLANK(termine!#ref!),"",termine!#ref!) -> #NAME?
A11: =termine!#ref! -> #NAME? | B11: =IF(ISBLANK(termine!#ref!),"",termine!#ref!) -> #NAME? | C11: =IF(ISBLANK(termine!#ref!),"",termine!#ref!) -> #NAME? | D11: =IF(ISBLANK(termine!#ref!),"",termine!#ref!) -> #NAME? | E11: =IF(ISBLANK(termine!#ref!),"",termine!#ref!) -> #NAME? | F11: =IF(ISBLANK(termine!#ref!),"",termine!#ref!) -> #NAME? | G11: =IF(ISBLANK(termine!#ref!),"",termine!#ref!) -> #NAME? | H11: =IF(ISBLANK(termine!#ref!),"",termine!#ref!) -> #NAME?
A12: =termine!#ref! -> #NAME? | B12: =IF(ISBLANK(termine!#ref!),"",termine!#ref!) -> #NAME? | C12: =IF(ISBLANK(termine!#ref!),"",termine!#ref!) -> #NAME? | D12: =IF(ISBLANK(termine!#ref!),"",termine!#ref!) -> #NAME? | E12: =IF(ISBLANK(termine!#ref!),"",termine!#ref!) -> #NAME? | F12: =IF(ISBLANK(termine!#ref!),"",termine!#ref!) -> #NAME? | G12: =IF(ISBLANK(termine!#ref!),"",termine!#ref!) -> #NAME? | H12: =IF(ISBLANK(termine!#ref!),"",termine!#ref!) -> #NAME?
A13: =termine!#ref! -> #NAME? | B13: =IF(ISBLANK(termine!#ref!),"",termine!#ref!) -> #NAME? | C13: =IF(ISBLANK(termine!#ref!),"",termine!#ref!) -> #NAME? | D13: =IF(ISBLANK(termine!#ref!),"",termine!#ref!) -> #NAME? | E13: =IF(ISBLANK(termine!#ref!),"",termine!#ref!) -> #NAME? | F13: =IF(ISBLANK(termine!#ref!),"",termine!#ref!) -> #NAME? | G13: =IF(ISBLANK(termine!#ref!),"",termine!#ref!) -> #NAME? | H13: =IF(ISBLANK(termine!#ref!),"",termine!#ref!) -> #NAME?
... A190: =termine!#ref! -> #NAME? | B190: =IF(ISBLANK(termine!#ref!),"",termine!#ref!) -> #NAME? | C190: =IF(ISBLANK(termine!#ref!),"",termine!#ref!) -> #NAME? | D190: =IF(ISBLANK(termine!#ref!),"",termine!#ref!) -> #NAME? | E190: =IF(ISBLANK(termine!#ref!),"",termine!#ref!) -> #NAME? | F190: =IF(ISBLANK(termine!#ref!),"",termine!#ref!) -> #NAME? | G190: =IF(ISBLANK(termine!#ref!),"",termine!#ref!) -> #NAME? | H190: =IF(ISBLANK(termine!#ref!),"",termine!#ref!) -> #NAME?
